[2025-01-12T16:33:26.235+0000] {local_task_job_runner.py:123} INFO - ::group::Pre task execution logs
[2025-01-12T16:33:26.254+0000] {taskinstance.py:2613} INFO - Dependencies all met for dep_context=non-requeueable deps ti=<TaskInstance: xgboost_drift_pipeline.test_prediction_after_retrain scheduled__2025-01-01T17:00:00+00:00 [queued]>
[2025-01-12T16:33:26.265+0000] {taskinstance.py:2613} INFO - Dependencies all met for dep_context=requeueable deps ti=<TaskInstance: xgboost_drift_pipeline.test_prediction_after_retrain scheduled__2025-01-01T17:00:00+00:00 [queued]>
[2025-01-12T16:33:26.267+0000] {taskinstance.py:2866} INFO - Starting attempt 1 of 2
[2025-01-12T16:33:26.282+0000] {taskinstance.py:2889} INFO - Executing <Task(PythonOperator): test_prediction_after_retrain> on 2025-01-01 17:00:00+00:00
[2025-01-12T16:33:26.292+0000] {standard_task_runner.py:72} INFO - Started process 319 to run task
[2025-01-12T16:33:26.296+0000] {standard_task_runner.py:104} INFO - Running: ['***', 'tasks', 'run', 'xgboost_drift_pipeline', 'test_prediction_after_retrain', 'scheduled__2025-01-01T17:00:00+00:00', '--job-id', '56', '--raw', '--subdir', 'DAGS_FOLDER/train_xgboost_pipeline.py', '--cfg-path', '/tmp/tmpufhfs1wm']
[2025-01-12T16:33:26.300+0000] {standard_task_runner.py:105} INFO - Job 56: Subtask test_prediction_after_retrain
[2025-01-12T16:33:26.317+0000] {logging_mixin.py:190} WARNING - /usr/local/lib/python3.10/site-packages/***/settings.py:209 DeprecationWarning: The sql_alchemy_conn option in [core] has been moved to the sql_alchemy_conn option in [database] - the old setting has been used, but please update your config.
[2025-01-12T16:33:26.360+0000] {task_command.py:467} INFO - Running <TaskInstance: xgboost_drift_pipeline.test_prediction_after_retrain scheduled__2025-01-01T17:00:00+00:00 [running]> on host 42dc6dafdabb
[2025-01-12T16:33:26.363+0000] {logging_mixin.py:190} WARNING - /usr/local/lib/python3.10/site-packages/***/settings.py:470 DeprecationWarning: The sql_alchemy_conn option in [core] has been moved to the sql_alchemy_conn option in [database] - the old setting has been used, but please update your config.
[2025-01-12T16:33:26.458+0000] {taskinstance.py:3132} INFO - Exporting env vars: AIRFLOW_CTX_DAG_OWNER='***' AIRFLOW_CTX_DAG_ID='xgboost_drift_pipeline' AIRFLOW_CTX_TASK_ID='test_prediction_after_retrain' AIRFLOW_CTX_EXECUTION_DATE='2025-01-01T17:00:00+00:00' AIRFLOW_CTX_TRY_NUMBER='1' AIRFLOW_CTX_DAG_RUN_ID='scheduled__2025-01-01T17:00:00+00:00'
[2025-01-12T16:33:26.460+0000] {taskinstance.py:731} INFO - ::endgroup::
[2025-01-12T16:33:26.492+0000] {train_xgboost_pipeline.py:837} INFO - Testing prediction on current data...
[2025-01-12T16:33:26.570+0000] {train_xgboost_pipeline.py:674} INFO - Downloaded data/Ingestion/Financial_with_Sentiment_pseudo.csv from MinIO to /tmp/Financial_with_Sentiment_pseudo.csv
[2025-01-12T16:33:26.600+0000] {train_xgboost_pipeline.py:674} INFO - Downloaded data/Ingestion/retrained_model_test.pkl from MinIO to /tmp/retrained_model_test.pkl
[2025-01-12T16:33:26.615+0000] {taskinstance.py:3311} ERROR - Task failed with exception
Traceback (most recent call last):
  File "/usr/local/lib/python3.10/site-packages/airflow/models/taskinstance.py", line 767, in _execute_task
    result = _execute_callable(context=context, **execute_callable_kwargs)
  File "/usr/local/lib/python3.10/site-packages/airflow/models/taskinstance.py", line 733, in _execute_callable
    return ExecutionCallableRunner(
  File "/usr/local/lib/python3.10/site-packages/airflow/utils/operator_helpers.py", line 252, in run
    return self.func(*args, **kwargs)
  File "/usr/local/lib/python3.10/site-packages/airflow/models/baseoperator.py", line 422, in wrapper
    return func(self, *args, **kwargs)
  File "/usr/local/lib/python3.10/site-packages/airflow/operators/python.py", line 238, in execute
    return_value = self.execute_callable()
  File "/usr/local/lib/python3.10/site-packages/airflow/operators/python.py", line 256, in execute_callable
    return runner.run(*self.op_args, **self.op_kwargs)
  File "/usr/local/lib/python3.10/site-packages/airflow/utils/operator_helpers.py", line 252, in run
    return self.func(*args, **kwargs)
  File "/app/dags/train_xgboost_pipeline.py", line 852, in test_prediction_after_retrain
    current_df = pd.read_csv(current_file)
  File "/usr/local/lib/python3.10/site-packages/pandas/io/parsers/readers.py", line 1026, in read_csv
    return _read(filepath_or_buffer, kwds)
  File "/usr/local/lib/python3.10/site-packages/pandas/io/parsers/readers.py", line 620, in _read
    parser = TextFileReader(filepath_or_buffer, **kwds)
  File "/usr/local/lib/python3.10/site-packages/pandas/io/parsers/readers.py", line 1620, in __init__
    self._engine = self._make_engine(f, self.engine)
  File "/usr/local/lib/python3.10/site-packages/pandas/io/parsers/readers.py", line 1898, in _make_engine
    return mapping[engine](f, **self.options)
  File "/usr/local/lib/python3.10/site-packages/pandas/io/parsers/c_parser_wrapper.py", line 93, in __init__
    self._reader = parsers.TextReader(src, **kwds)
  File "parsers.pyx", line 581, in pandas._libs.parsers.TextReader.__cinit__
pandas.errors.EmptyDataError: No columns to parse from file
[2025-01-12T16:33:26.644+0000] {taskinstance.py:1225} INFO - Marking task as UP_FOR_RETRY. dag_id=xgboost_drift_pipeline, task_id=test_prediction_after_retrain, run_id=scheduled__2025-01-01T17:00:00+00:00, execution_date=20250101T170000, start_date=20250112T163326, end_date=20250112T163326
[2025-01-12T16:33:26.672+0000] {taskinstance.py:340} INFO - ::group::Post task execution logs
[2025-01-12T16:33:26.673+0000] {standard_task_runner.py:124} ERROR - Failed to execute job 56 for task test_prediction_after_retrain (No columns to parse from file; 319)
Traceback (most recent call last):
  File "/usr/local/lib/python3.10/site-packages/airflow/task/task_runner/standard_task_runner.py", line 117, in _start_by_fork
    ret = args.func(args, dag=self.dag)
  File "/usr/local/lib/python3.10/site-packages/airflow/cli/cli_config.py", line 49, in command
    return func(*args, **kwargs)
  File "/usr/local/lib/python3.10/site-packages/airflow/utils/cli.py", line 116, in wrapper
    return f(*args, **kwargs)
  File "/usr/local/lib/python3.10/site-packages/airflow/cli/commands/task_command.py", line 483, in task_run
    task_return_code = _run_task_by_selected_method(args, _dag, ti)
  File "/usr/local/lib/python3.10/site-packages/airflow/cli/commands/task_command.py", line 256, in _run_task_by_selected_method
    return _run_raw_task(args, ti)
  File "/usr/local/lib/python3.10/site-packages/airflow/cli/commands/task_command.py", line 341, in _run_raw_task
    return ti._run_raw_task(
  File "/usr/local/lib/python3.10/site-packages/airflow/utils/session.py", line 97, in wrapper
    return func(*args, session=session, **kwargs)
  File "/usr/local/lib/python3.10/site-packages/airflow/models/taskinstance.py", line 3005, in _run_raw_task
    return _run_raw_task(
  File "/usr/local/lib/python3.10/site-packages/airflow/models/taskinstance.py", line 273, in _run_raw_task
    TaskInstance._execute_task_with_callbacks(
  File "/usr/local/lib/python3.10/site-packages/airflow/models/taskinstance.py", line 3159, in _execute_task_with_callbacks
    result = self._execute_task(context, task_orig)
  File "/usr/local/lib/python3.10/site-packages/airflow/models/taskinstance.py", line 3183, in _execute_task
    return _execute_task(self, context, task_orig)
  File "/usr/local/lib/python3.10/site-packages/airflow/models/taskinstance.py", line 767, in _execute_task
    result = _execute_callable(context=context, **execute_callable_kwargs)
  File "/usr/local/lib/python3.10/site-packages/airflow/models/taskinstance.py", line 733, in _execute_callable
    return ExecutionCallableRunner(
  File "/usr/local/lib/python3.10/site-packages/airflow/utils/operator_helpers.py", line 252, in run
    return self.func(*args, **kwargs)
  File "/usr/local/lib/python3.10/site-packages/airflow/models/baseoperator.py", line 422, in wrapper
    return func(self, *args, **kwargs)
  File "/usr/local/lib/python3.10/site-packages/airflow/operators/python.py", line 238, in execute
    return_value = self.execute_callable()
  File "/usr/local/lib/python3.10/site-packages/airflow/operators/python.py", line 256, in execute_callable
    return runner.run(*self.op_args, **self.op_kwargs)
  File "/usr/local/lib/python3.10/site-packages/airflow/utils/operator_helpers.py", line 252, in run
    return self.func(*args, **kwargs)
  File "/app/dags/train_xgboost_pipeline.py", line 852, in test_prediction_after_retrain
    current_df = pd.read_csv(current_file)
  File "/usr/local/lib/python3.10/site-packages/pandas/io/parsers/readers.py", line 1026, in read_csv
    return _read(filepath_or_buffer, kwds)
  File "/usr/local/lib/python3.10/site-packages/pandas/io/parsers/readers.py", line 620, in _read
    parser = TextFileReader(filepath_or_buffer, **kwds)
  File "/usr/local/lib/python3.10/site-packages/pandas/io/parsers/readers.py", line 1620, in __init__
    self._engine = self._make_engine(f, self.engine)
  File "/usr/local/lib/python3.10/site-packages/pandas/io/parsers/readers.py", line 1898, in _make_engine
    return mapping[engine](f, **self.options)
  File "/usr/local/lib/python3.10/site-packages/pandas/io/parsers/c_parser_wrapper.py", line 93, in __init__
    self._reader = parsers.TextReader(src, **kwds)
  File "parsers.pyx", line 581, in pandas._libs.parsers.TextReader.__cinit__
pandas.errors.EmptyDataError: No columns to parse from file
[2025-01-12T16:33:26.713+0000] {local_task_job_runner.py:266} INFO - Task exited with return code 1
[2025-01-12T16:33:26.740+0000] {taskinstance.py:3895} INFO - 0 downstream tasks scheduled from follow-on schedule check
[2025-01-12T16:33:26.743+0000] {local_task_job_runner.py:245} INFO - ::endgroup::
